Workbook

Sheet hidden
A1: b420c00c-cd5c-42ab-a8fc-1d8589e80ae7
A2: V2

Sheet Fornecedores
A1: Fornecedor | B1: Código
A2: Importação | B2: 1
A3: SPARE | B3: 2
A4: LT CORREA | B4: 3
A5: MultiKit | B5: 4
A6: HOLYMAN | B6: 5
A7: MundiFlex | B7: 6
A8: POLO | B8: 7
A9: BRK | B9: 8
A10: AMW | B10: 9
A11: MOBENSANI | B11: 10
A12: Replabor | B12: 11
A13: IRB | B13: 12
... A27: ALENCAR | B27: 26

Sheet 2024
I1: =SUBTOTAL(9,I3:I3281) -> 12380 | J1: =SUBTOTAL(9,J3:J1310) -> 1611 | K1: =SUBTOTAL(9,K3:K1310) -> 3994 | L1: =SUBTOTAL(9,L3:L1310) -> 5904 | M1: =SUBTOTAL(9,M3:M1310) -> 738 | N1: =SUBTOTAL(9,N3:N3281) -> 9146 | O1: 1303 | P1: =SUBTOTAL(9,P3:P1310) -> 3262 | Q1: =SUBTOTAL(9,Q3:Q3228) -> 4575 | R1: =SUBTOTAL(9,R3:R3281) -> 6913 | S1: =SUBTOTAL(9,S3:S3281) -> 1363 | T1: =SUBTOTAL(9,T3:T3281) -> 3635 | U1: =SUBTOTAL(9,U3:U3281) -> 1857 | V1: =SUBTOTAL(9,V3:V3281) -> 12550 | W1: =SUBTOTAL(9,W3:W3281) -> 1664 | X1: =SUBTOTAL(9,X3:X3281) -> 4410 | Y1: =SUBTOTAL(9,Y3:Y3281) -> 6444 | ... AB1: =SUBTOTAL(9,AB3:AB3281) -> 4441 | AC1: 5348 | AD1: =SUBTOTAL(9,AD3:AD3281) -> 14307 | AE1: =SUBTOTAL(9,AE3:AE3281) -> 1425 | AF1: =SUBTOTAL(9,AF3:AF3281) -> 4740 | AG1: =SUBTOTAL(9,AG3:AG3281) -> 8137 | AH1: =SUBTOTAL(9,AH3:AH3281) -> 14423 | AI1: =SUBTOTAL(9,AI3:AI3281) -> 1332 | AJ1: =SUBTOTAL(9,AJ3:AJ3281) -> 4923 | AK1: =SUBTOTAL(9,AK3:AK3281) -> 8168 | ... BA1: =SUBTOTAL(9,BA3:BA3281) -> 8901 | BB1: =IFERROR(AY1/BA1-1,"") -> 0.22732527 | BC1: =SUBTOTAL(9,BC3:BC3281) -> 0 | BD1: =SUBTOTAL(9,BD3:BD3281) -> 0 | BE1: =SUBTOTAL(9,BE3:BE3281) -> 0 | BF1: =SUBTOTAL(9,BF3:BF3281) -> 0 | BH1: =SUBTOTAL(9,BH3:BH3281) -> 10940.683
A2: SKU | B2: Anúnciado? | C2: Seguimento | D2: Categoria | E2: Fornecedor | F2: CÓDIGO FORNECEDOR | G2: Descrição / Aplicação | H2: Mini Gráfico | I2: Janeiro | J2: Vendas Unitárias | K2: Vendas KIT | L2: Vendas Direta / Distribuidor | M2: VENDAS Adilson / Yasmin | N2: Fevereiro | O2: Vendas Unitárias ML | P2: Vendas KIT ML | Q2: Vendas Direta / Distribuidor | R2: Março | S2: Vendas Unitárias ML | T2: Vendas KIT ML | U2: Vendas Direta / Distribuidor | V2: Abril | W2: Vendas Unitárias ML | X2: Vendas KIT ML | Y2: Vendas Direta / Distribuidor | Z2: Maio | AA2: Vendas Unitárias ML | AB2: Vendas KIT ML | AC2: Vendas Direta / Distribuidor | AD2: Junho | AE2: Vendas Unitárias ML | AF2: Vendas KIT ML | AG2: Vendas Direta / Distribuidor | AH2: Julho | AI2: Vendas Unitárias ML | AJ2: Vendas KIT ML | AK2: Vendas Direta / Distribuidor | AL2: Agosto | AM2: Vendas Unitárias ML | AN2: Vendas KIT ML | AO2: Vendas Direta / Distribuidor | AP2: Setembro | AQ2: Vendas Unitárias | AR2: Vendas KIT | AS2: Outubro | AT2: Vendas Unitárias | AU2: Vendas KIT | AV2: Venda Direta | AW2: Novembro | AX2: Dezembro | AY2: MÉDIA 2024 | AZ2: Estoque | BA2: MÉDIA 2023 | BB2: Oscilação | BC2: ESTOQUE | BD2: ESTOQUE Bandeja SEM BUCHA | BE2: ESTOQUE SUCATAS Bandeja | BF2: Total Estoque Bandeja | BG2: MESES DE ESTOQUE | BH2: SUGESTÃO PEDIDO
A3: VW001 | B3: Sim | C3: AUTOMOTIVO | D3: Rolamento Eixo | E3: Importação / Polo | F3: =IFERROR(VLOOKUP(E3,Fornecedores!$A$2:$B$2700,2,FALSE),"") | G3: Kit De Rolamento Roda Traseira Versailles 1992 A 1996 | I3: =SUM(J3:M3) -> 2803 | J3: 27 | K3: 1366 | L3: 1400 | M3: 10 | N3: =SUM(O3:Q3) -> 2368 | O3: 32 | P3: 1096 | Q3: 1240 | R3: =SUM(S3:U3) -> 1583 | S3: 18 | T3: 1495 | U3: 70 | V3: 2804 | W3: 3 | X3: 1671 | Y3: 1130 | Z3: 2797 | AA3: 1 | AB3: 1696 | AC3: 1100 | AD3: =SUM(AE3:AG3) -> 3112 | AE3: 10 | AF3: 1802 | AG3: 1300 | AH3: =SUM(AI3:AK3) -> 5563 | AI3: 1 | AJ3: 2112 | AK3: 3450 | AL3: =SUM(AM3:AO3) -> 2499 | AM3: 1 | AN3: 2196 | AO3: 302 | AP3: =SUM(AQ3:AR3) -> 2028 | AQ3: =IFERROR(VLOOKUP(A3,[1]SIIMPLES!$A$2:$F$418,6,FALSE),0) -> 0 | AR3: 2028 | AS3: 1558 | AT3: 0 | AU3: 1537 | AV3: 21 | AY3: =IFERROR(AVERAGE(I3,N3,R3,V3,Z3,AD3,AH3,AL3,AP3,AS3,AW3,AX3),"-") -> 2711.5 | BA3: 2495.3333
A4: 332052 | B4: Sim | C4: AUTOMOTIVO | D4: Bandeja | E4: SPARE | F4: =IFERROR(VLOOKUP(E4,Fornecedores!$A$2:$B$2700,2,FALSE),"") -> 2 | G4: Morceguinho Dianteiro Classic Lado Direito 2004 A 2015 | I4: =SUM(J4:M4) -> 1015 | J4: 5 | K4: 218 | L4: 620 | M4: 172 | N4: =SUM(O4:Q4) -> 1081 | O4: 12 | P4: 259 | Q4: 810 | R4: =SUM(S4:U4) -> 723 | S4: 6 | T4: 241 | U4: 476 | V4: 2261 | W4: 3 | X4: 255 | Y4: 2003 | Z4: 1943 | AA4: 4 | AB4: 283 | AC4: 1656 | AD4: =SUM(AE4:AG4) -> 2978 | AE4: 2 | AF4: 255 | AG4: 2721 | AH4: =SUM(AI4:AK4) -> 1008 | AI4: 1 | AJ4: 297 | AK4: 710 | AL4: =SUM(AM4:AO4) -> 1091 | AM4: 1 | AN4: 260 | AO4: 830 | AP4: =SUM(AQ4:AR4) -> 840 | AQ4: =IFERROR(VLOOKUP(A4,[1]SIIMPLES!$A$2:$F$418,6,FALSE),0) -> 628 | AR4: 212 | AS4: 622 | AT4: 2 | AU4: 170 | AV4: 450 | AY4: =IFERROR(AVERAGE(I4,N4,R4,V4,Z4,AD4,AH4,AL4,AP4,AS4,AW4,AX4),"-") -> 1356.2 | BA4: 334.66667 | BB4: =IFERROR(AY4/BA4-1,"") -> 3.0523904 | BG4: =IFERROR(BC4/AY4,"0") -> 0 | BH4: =IFERROR(IF(F4=1,IF(BC4<AY4*3,AY4*3-BC4,0),IF(BC4<AY4,AY4-BC4,0)),"") -> 1356.2
A5: 332053 | B5: Sim | C5: AUTOMOTIVO | D5: Bandeja | E5: SPARE | F5: =IFERROR(VLOOKUP(E5,Fornecedores!$A$2:$B$2700,2,FALSE),"") -> 2 | G5: Morceguinho Dianteiro Classic Lado Esquerdo 2004 A 2015 | I5: =SUM(J5:M5) -> 1013 | J5: 4 | K5: 218 | L5: 620 | M5: 171 | N5: =SUM(O5:Q5) -> 972 | O5: 3 | P5: 259 | Q5: 710 | R5: =SUM(S5:U5) -> 710 | S5: 3 | T5: 241 | U5: 466 | V5: 2261 | W5: 3 | X5: 255 | Y5: 2003 | Z5: 1941 | AA5: 2 | AB5: 283 | AC5: 1656 | AD5: =SUM(AE5:AG5) -> 2987 | AE5: 1 | AF5: 255 | AG5: 2731 | AH5: =SUM(AI5:AK5) -> 1014 | AI5: 6 | AJ5: 297 | AK5: 711 | AL5: =SUM(AM5:AO5) -> 1091 | AM5: 1 | AN5: 260 | AO5: 830 | AP5: =SUM(AQ5:AR5) -> 749 | AQ5: =IFERROR(VLOOKUP(A5,[1]SIIMPLES!$A$2:$F$418,6,FALSE),0) -> 537 | AR5: 212 | AS5: 419 | AT5: 2 | AU5: 170 | AV5: 247 | AY5: =IFERROR(AVERAGE(I5,N5,R5,V5,Z5,AD5,AH5,AL5,AP5,AS5,AW5,AX5),"-") -> 1315.7 | BA5: 330.5 | BB5: =IFERROR(AY5/BA5-1,"") -> 2.980938 | BG5: =IFERROR(BC5/AY5,"0") -> 0 | BH5: =IFERROR(IF(F5=1,IF(BC5<AY5*3,AY5*3-BC5,0),IF(BC5<AY5,AY5-BC5,0)),"") -> 1315.7
A6: PF005 | B6: Sim | C6: AUTOMOTIVO | D6: Rolamento Eixo | E6: Importação | F6: =IFERROR(VLOOKUP(E6,Fornecedores!$A$2:$B$2700,2,FALSE),"") -> 1 | G6: Reparo Traseiro Rolamento Blindado Palio Weekend Marea Brava | I6: =SUM(J6:M6) -> 322 | J6: 2 | K6: 20 | L6: 300 | M6: 0 | N6: =SUM(O6:Q6) -> 94 | O6: 2 | P6: 32 | Q6: 60 | R6: =SUM(S6:U6) -> 101 | S6: 3 | T6: 48 | U6: 50 | V6: 549 | W6: 11 | X6: 68 | Y6: 470 | Z6: 355 | AA6: 3 | AB6: 52 | AC6: 300 | AD6: =SUM(AE6:AG6) -> 196 | AE6: 4 | AF6: 92 | AG6: 100 | AH6: =SUM(AI6:AK6) -> 127 | AI6: 9 | AJ6: 78 | AK6: 40 | AL6: =SUM(AM6:AO6) -> 32 | AN6: 32 | AO6: 0 | AP6: =SUM(AQ6:AR6) -> 628 | AQ6: =IFERROR(VLOOKUP(A6,[1]SIIMPLES!$A$2:$F$418,6,FALSE),0) -> 602 | AR6: 26 | AS6: 182 | AT6: 112 | AU6: 66 | AV6: 4 | AY6: =IFERROR(AVERAGE(I6,N6,R6,V6,Z6,AD6,AH6,AL6,AP6,AS6,AW6,AX6),"-") -> 258.6 | BA6: 107.66667 | BB6: =IFERROR(AY6/BA6-1,"") -> 1.4018576 | BG6: =IFERROR(BC6/AY6,"0") -> 0 | BH6: =IFERROR(IF(F6=1,IF(BC6<AY6*3,AY6*3-BC6,0),IF(BC6<AY6,AY6-BC6,0)),"") -> 775.8
A7: 77350 | B7: Sim | C7: AUTOMOTIVO | D7: Cabo Câmbio | E7: Importação | F7: =IFERROR(VLOOKUP(E7,Fornecedores!$A$2:$B$2700,2,FALSE),"") -> 1 | G7: Cabo De Trambulador Corsa Classic 2005/2014 | I7: =SUM(J7:M7) -> 459 | J7: 137 | K7: 42 | L7: 280 | M7: 0 | N7: =SUM(O7:Q7) -> 664 | O7: 114 | P7: 40 | Q7: 510 | R7: =SUM(S7:U7) -> 301 | S7: 112 | T7: 39 | U7: 150 | V7: 104 | W7: 32 | X7: 27 | Y7: 45 | Z7: 20 | AA7: 19 | AB7: 1 | AC7: 0 | AD7: =SUM(AE7:AG7) -> 19 | AE7: 18 | AF7: 1 | AG7: 0 | AH7: =SUM(AI7:AK7) -> 406 | AI7: 6 | AJ7: 0 | AK7: 400 | AL7: =SUM(AM7:AO7) -> 398 | AM7: 87 | AN7: 30 | AO7: 281 | AP7: =SUM(AQ7:AR7) -> 322 | AQ7: =IFERROR(VLOOKUP(A7,[1]SIIMPLES!$A$2:$F$418,6,FALSE),0) -> 285 | AR7: 37 | AS7: 76 | AT7: 0 | AU7: 46 | AV7: 30 | AY7: =IFERROR(AVERAGE(I7,N7,R7,V7,Z7,AD7,AH7,AL7,AP7,AS7,AW7,AX7),"-") -> 276.9 | BA7: 466.33333 | BB7: =IFERROR(AY7/BA7-1,"") -> -0.40621873 | BG7: =IFERROR(BC7/AY7,"0") -> 0 | BH7: =IFERROR(IF(F7=1,IF(BC7<AY7*3,AY7*3-BC7,0),IF(BC7<AY7,AY7-BC7,0)),"") -> 830.7
A8: 332042 | B8: Sim | C8: AUTOMOTIVO | D8: Bandeja | E8: SPARE | F8: =IFERROR(VLOOKUP(E8,Fornecedores!$A$2:$B$2700,2,FALSE),"") -> 2 | G8: Morceguinho Lado Direito Corsa 1994 A 1998 | I8: =SUM(J8:M8) -> 22 | J8: 0 | K8: 11 | L8: 0 | M8: 11 | N8: =SUM(O8:Q8) -> 57 | O8: 0 | P8: 7 | Q8: 50 | R8: =SUM(S8:U8) -> 10 | S8: 0 | T8: 10 | U8: 0 | V8: 5 | W8: 0 | X8: 5 | Y8: 0 | Z8: 2 | AA8: 0 | AB8: 2 | AC8: 0 | AD8: =SUM(AE8:AG8) -> 4 | AE8: 0 | AF8: 1 | AG8: 3 | AH8: =SUM(AI8:AK8) -> 34 | AI8: 0 | AJ8: 2 | AK8: 32 | AL8: =SUM(AM8:AO8) -> 0 | AN8: 0 | AO8: 0 | AP8: =SUM(AQ8:AR8) -> 169 | AQ8: =IFERROR(VLOOKUP(A8,[1]SIIMPLES!$A$2:$F$418,6,FALSE),0) -> 169 | AR8: 0 | AS8: 1 | AT8: 0 | AU8: 1 | AV8: 0 | AY8: =IFERROR(AVERAGE(I8,N8,R8,V8,Z8,AD8,AH8,AL8,AP8,AS8,AW8,AX8),"-") -> 30.4 | BA8: 10 | BB8: =IFERROR(AY8/BA8-1,"") -> 2.04 | BG8: =IFERROR(BC8/AY8,"0") -> 0 | BH8: =IFERROR(IF(F8=1,IF(BC8<AY8*3,AY8*3-BC8,0),IF(BC8<AY8,AY8-BC8,0)),"") -> 30.4
A9: 20W50-M | C9: AUTOMOTIVO | D9: Óleo Motor | E9: =VLOOKUP(A9,[2]CMV!$A$1:$E$2043,5,FALSE) -> 0 | F9: =IFERROR(VLOOKUP(E9,Fornecedores!$A$2:$B$2700,2,FALSE),"") | G9: =VLOOKUP(A9,[2]CMV!$A$1:$F$2043,6,FALSE) -> 0 | I9: =SUM(J9:M9) -> 0 | J9: 0 | K9: 0 | L9: 0 | M9: 0 | N9: =SUM(O9:Q9) -> 0 | O9: 0 | P9: 0 | Q9: 0 | R9: =SUM(S9:U9) -> 0 | S9: 0 | T9: 0 | U9: 0 | V9: 78 | W9: 0 | X9: 0 | Y9: 78 | Z9: 35 | AA9: 0 | AB9: 0 | AC9: 35 | AD9: =SUM(AE9:AG9) -> 96 | AE9: 0 | AF9: 0 | AG9: 96 | AH9: =SUM(AI9:AK9) -> 56 | AI9: 0 | AJ9: 0 | AK9: 56 | AL9: =SUM(AM9:AO9) -> 73 | AN9: 0 | AO9: 73 | AP9: =SUM(AQ9:AR9) -> 168 | AQ9: =IFERROR(VLOOKUP(A9,[1]SIIMPLES!$A$2:$F$418,6,FALSE),0) -> 168 | AR9: 0 | AS9: 0 | AT9: 0 | AU9: 0 | AV9: 0 | AY9: =IFERROR(AVERAGE(I9,N9,R9,V9,Z9,AD9,AH9,AL9,AP9,AS9,AW9,AX9),"-") -> 50.6 | BA9: 0 | BB9: =IFERROR(AY9/BA9-1,"") | BF9: =SUM(BC9:BE9) -> 0 | BG9: =IFERROR(BC9/AY9,"0") -> 0 | BH9: =IFERROR(IF(F9=1,IF(BC9<AY9*3,AY9*3-BC9,0),IF(BC9<AY9,AY9-BC9,0)),"") -> 50.6
A10: 332043 | B10: Sim | C10: AUTOMOTIVO | D10: Bandeja | E10: SPARE | F10: =IFERROR(VLOOKUP(E10,Fornecedores!$A$2:$B$2700,2,FALSE),"") -> 2 | G10: Morceguinho Lado Esquerdo Corsa 1994 A 1998 | I10: =SUM(J10:M10) -> 22 | J10: 0 | K10: 11 | L10: 0 | M10: 11 | N10: =SUM(O10:Q10) -> 57 | O10: 0 | P10: 7 | Q10: 50 | R10: =SUM(S10:U10) -> 10 | S10: 0 | T10: 10 | U10: 0 | V10: 5 | W10: 0 | X10: 5 | Y10: 0 | Z10: 2 | AA10: 0 | AB10: 2 | AC10: 0 | AD10: =SUM(AE10:AG10) -> 4 | AE10: 0 | AF10: 1 | AG10: 3 | AH10: =SUM(AI10:AK10) -> 8 | AI10: 0 | AJ10: 2 | AK10: 6 | AL10: =SUM(AM10:AO10) -> 0 | AN10: 0 | AO10: 0 | AP10: =SUM(AQ10:AR10) -> 149 | AQ10: =IFERROR(VLOOKUP(A10,[1]SIIMPLES!$A$2:$F$418,6,FALSE),0) -> 149 | AR10: 0 | AS10: 26 | AT10: 25 | AU10: 1 | AV10: 0 | AY10: =IFERROR(AVERAGE(I10,N10,R10,V10,Z10,AD10,AH10,AL10,AP10,AS10,AW10,AX10),"-") -> 28.3 | BA10: 10 | BB10: =IFERROR(AY10/BA10-1,"") -> 1.83 | BF10: =SUM(BC10:BE10) -> 0 | BG10: =IFERROR(BC10/AY10,"0") -> 0 | BH10: =IFERROR(IF(F10=1,IF(BC10<AY10*3,AY10*3-BC10,0),IF(BC10<AY10,AY10-BC10,0)),"") -> 28.3
A11: PG001 | B11: Sim | C11: AUTOMOTIVO | D11: Rolamento Eixo | E11: Importação | F11: =IFERROR(VLOOKUP(E11,Fornecedores!$A$2:$B$2700,2,FALSE),"") -> 1 | G11: Reparo Rolamento Eixo Traseiro Pegeout 207 47mm 2008 A 2010 | I11: =SUM(J11:M11) -> 209 | J11: 29 | K11: 166 | L11: 0 | M11: 14 | N11: =SUM(O11:Q11) -> 187 | O11: 11 | P11: 166 | Q11: 10 | R11: =SUM(S11:U11) -> 293 | S11: 23 | T11: 242 | U11: 28 | V11: 312 | W11: 50 | X11: 232 | Y11: 30 | Z11: 347 | AA11: 25 | AB11: 292 | AC11: 30 | AD11: =SUM(AE11:AG11) -> 286 | AE11: 24 | AF11: 248 | AG11: 14 | AH11: =SUM(AI11:AK11) -> 291 | AI11: 44 | AJ11: 230 | AK11: 17 | AL11: =SUM(AM11:AO11) -> 256 | AM11: 30 | AN11: 188 | AO11: 38 | AP11: =SUM(AQ11:AR11) -> 148 | AQ11: =IFERROR(VLOOKUP(A11,[1]SIIMPLES!$A$2:$F$418,6,FALSE),0) -> 22 | AR11: 126 | AS11: 186 | AT11: 6 | AU11: 160 | AV11: 20 | AY11: =IFERROR(AVERAGE(I11,N11,R11,V11,Z11,AD11,AH11,AL11,AP11,AS11,AW11,AX11),"-") -> 251.5 | BA11: 236 | BB11: =IFERROR(AY11/BA11-1,"") -> 0.065677966 | BG11: =IFERROR(BC11/AY11,"0") -> 0 | BH11: =IFERROR(IF(F11=1,IF(BC11<AY11*3,AY11*3-BC11,0),IF(BC11<AY11,AY11-BC11,0)),"") -> 754.5
A12: 112005 | B12: Sim | C12: AUTOMOTIVO | D12: Bandeja | E12: SPARE | F12: =IFERROR(VLOOKUP(E12,Fornecedores!$A$2:$B$2700,2,FALSE),"") -> 2 | G12: Bracinho Oscilante Com Pivô Uno 2002 A 2011 | I12: =SUM(J12:M12) -> 116 | J12: 16 | K12: 48 | L12: 0 | M12: 52 | N12: =SUM(O12:Q12) -> 532 | O12: 6 | P12: 44 | Q12: 482 | R12: =SUM(S12:U12) -> 43 | S12: 1 | T12: 32 | U12: 10 | V12: 91 | W12: 5 | X12: 16 | Y12: 70 | Z12: 97 | AA12: 1 | AB12: 26 | AC12: 70 | AD12: =SUM(AE12:AG12) -> 156 | AE12: 11 | AF12: 45 | AG12: 100 | AH12: =SUM(AI12:AK12) -> 507 | AI12: 1 | AJ12: 48 | AK12: 458 | AL12: =SUM(AM12:AO12) -> 89 | AM12: 7 | AN12: 32 | AO12: 50 | AP12: =SUM(AQ12:AR12) -> 118 | AQ12: =IFERROR(VLOOKUP(A12,[1]SIIMPLES!$A$2:$F$418,6,FALSE),0) -> 82 | AR12: 36 | AS12: 257 | AT12: 30 | AU12: 18 | AV12: 209 | AY12: =IFERROR(AVERAGE(I12,N12,R12,V12,Z12,AD12,AH12,AL12,AP12,AS12,AW12,AX12),"-") -> 200.6 | BA12: 86 | BB12: =IFERROR(AY12/BA12-1,"") -> 1.3325581 | BF12: =SUM(BC12:BE12) -> 0 | BG12: =IFERROR(BC12/AY12,"0") -> 0 | BH12: =ROUND(IFERROR(IF(F12=1,IF(BC12<AY12*3,AY12*3-BC12,0),IF(BC12<AY12,AY12*0.6-BC12,0)),""),0) -> 120
A13: 14104 | B13: Sim | C13: AUTOMOTIVO | D13: Pino de Freio | E13: MultiKit | F13: =IFERROR(VLOOKUP(E13,Fornecedores!$A$2:$B$2700,2,FALSE),"") -> 4 | G13: Kit Pino Guia Bucha Pinça Freio Vw Crossfox Fox Gol Saveiro | I13: =SUM(J13:M13) -> 121 | J13: 13 | K13: 108 | L13: 0 | M13: 0 | N13: =SUM(O13:Q13) -> 90 | O13: 20 | P13: 70 | Q13: 0 | R13: =SUM(S13:U13) -> 61 | S13: 19 | T13: 36 | U13: 6 | V13: 129 | W13: 45 | X13: 84 | Y13: 0 | Z13: 87 | AA13: 15 | AB13: 72 | AC13: 0 | AD13: =SUM(AE13:AG13) -> 79 | AE13: 27 | AF13: 52 | AG13: 0 | AH13: =SUM(AI13:AK13) -> 45 | AI13: 9 | AJ13: 26 | AK13: 10 | AL13: =SUM(AM13:AO13) -> 102 | AM13: 30 | AN13: 72 | AO13: 0 | AP13: =SUM(AQ13:AR13) -> 95 | AQ13: =IFERROR(VLOOKUP(A13,[1]SIIMPLES!$A$2:$F$418,6,FALSE),0) -> 41 | AR13: 54 | AS13: 136 | AT13: 66 | AU13: 70 | AV13: 0 | AY13: =IFERROR(AVERAGE(I13,N13,R13,V13,Z13,AD13,AH13,AL13,AP13,AS13,AW13,AX13),"-") -> 94.5 | BA13: 132.66667 | BB13: =IFERROR(AY13/BA13-1,"") -> -0.28768844 | BG13: =IFERROR(BC13/AY13,"0") -> 0 | BH13: =IFERROR(IF(F13=1,IF(BC13<AY13*3,AY13*3-BC13,0),IF(BC13<AY13,AY13-BC13,0)),"") -> 94.5
A14: 77354 | C14: AUTOMOTIVO | D14: Cabo Câmbio | E14: Importação | F14: =IFERROR(VLOOKUP(E14,Fornecedores!$A$2:$B$2700,2,FALSE),"") -> 1 | G14: Cabo De Engate E Seleção Montana 2011 2012 2013 2014 Novo | I14: =SUM(J14:M14) -> 92 | J14: 40 | K14: 2 | L14: 50 | M14: 0 | N14: =SUM(O14:Q14) -> 67 | O14: 41 | P14: 1 | Q14: 25 | R14: =SUM(S14:U14) -> 100 | S14: 75 | T14: 4 | U14: 21 | V14: 119 | W14: 87 | X14: 2 | Y14: 30 | Z14: 35 | AA14: 35 | AB14: 0 | AC14: 0 | AD14: =SUM(AE14:AG14) -> 37 | AE14: 37 | AF14: 0 | AG14: 0 | AH14: =SUM(AI14:AK14) -> 11 | AI14: 11 | AJ14: 0 | AK14: 0 | AL14: =SUM(AM14:AO14) -> 59 | AM14: 42 | AN14: 3 | AO14: 14 | AP14: =SUM(AQ14:AR14) -> 83 | AQ14: =IFERROR(VLOOKUP(A14,[1]SIIMPLES!$A$2:$F$418,6,FALSE),0) -> 73 | AR14: 10 | AS14: 75 | AT14: 61 | AU14: 14 | AV14: 0 | AY14: =IFERROR(AVERAGE(I14,N14,R14,V14,Z14,AD14,AH14,AL14,AP14,AS14,AW14,AX14),"-") -> 67.8 | BA14: 5 | BB14: =IFERROR(AY14/BA14-1,"") -> 12.56 | BG14: =IFERROR(BC14/AY14,"0") -> 0 | BH14: =IFERROR(IF(F14=1,IF(BC14<AY14*3,AY14*3-BC14,0),IF(BC14<AY14,AY14-BC14,0)),"") -> 203.4
A15: 10107 | B15: Sim | C15: AUTOMOTIVO | D15: Bomba Combustível | E15: POLO | F15: =IFERROR(VLOOKUP(E15,Fornecedores!$A$2:$B$2700,2,FALSE),"") -> 7 | G15: Kit Bomba Combustível Gasolina Sistema Bosch Verona 94 A 96 | I15: =SUM(J15:M15) -> 65 | J15: 65 | K15: 0 | L15: 0 | M15: 0 | N15: =SUM(O15:Q15) -> 77 | O15: 77 | P15: 0 | Q15: 0 | R15: =SUM(S15:U15) -> 67 | S15: 67 | T15: 0 | U15: 0 | V15: 89 | W15: 89 | X15: 0 | Y15: 0 | Z15: 72 | AA15: 72 | AB15: 0 | AC15: 0 | AD15: =SUM(AE15:AG15) -> 49 | AE15: 49 | AF15: 0 | AG15: 0 | AH15: =SUM(AI15:AK15) -> 53 | AI15: 53 | AJ15: 0 | AK15: 0 | AL15: =SUM(AM15:AO15) -> 40 | AM15: 40 | AN15: 0 | AO15: 0 | AP15: =SUM(AQ15:AR15) -> 77 | AQ15: =IFERROR(VLOOKUP(A15,[1]SIIMPLES!$A$2:$F$418,6,FALSE),0) -> 77 | AR15: 0 | AS15: 0 | AT15: 0 | AU15: 0 | AV15: 0 | AY15: =IFERROR(AVERAGE(I15,N15,R15,V15,Z15,AD15,AH15,AL15,AP15,AS15,AW15,AX15),"-") -> 58.9 | BA15: 94.333333 | BB15: =IFERROR(AY15/BA15-1,"") -> -0.37561837 | BG15: =IFERROR(BC15/AY15,"0") -> 0 | BH15: =IFERROR(IF(F15=1,IF(BC15<AY15*3,AY15*3-BC15,0),IF(BC15<AY15,AY15-BC15,0)),"") -> 58.9
A16: 300621 | C16: =VLOOKUP(A16,[2]CMV!$A$1:$B$2115,2,FALSE) -> MOTO PEÇAS | D16: =VLOOKUP(A16,[2]CMV!$A$1:$C$2115,3,FALSE) -> ÓLEO MOTOR | E16: =VLOOKUP(A16,[2]CMV!$A$1:$E$2115,5,FALSE) -> SAKAMOTO | G16: =VLOOKUP(A16,[2]CMV!$A$1:$F$2115,6,FALSE) -> OLEO DE MOBIL 10W30 | AD16: =SUM(AE16:AG16) -> 24 | AG16: 24 | AH16: =SUM(AI16:AK16) -> 39 | AI16: 0 | AJ16: 0 | AK16: 39 | AL16: =SUM(AM16:AO16) -> 50 | AN16: 0 | AO16: 50 | AP16: =SUM(AQ16:AR16) -> 75 | AQ16: =IFERROR(VLOOKUP(A16,[1]SIIMPLES!$A$2:$F$418,6,FALSE),0) -> 75 | AR16: 0 | AS16: 61 | AT16: 0 | AU16: 0 | AV16: 61 | AY16: =IFERROR(AVERAGE(I16,N16,R16,V16,Z16,AD16,AH16,AL16,AP16,AS16,AW16,AX16),"-") -> 49.8 | BB16: =1-BA16/AY16 -> 1 | BG16: =IFERROR(BC16/AY16,"0") -> 0 | BH16: =IFERROR(IF(F16=1,IF(BC16<AY16*3,AY16*3-BC16,0),IF(BC16<AY16,AY16-BC16,0)),"") -> 49.8
A17: 300620 | C17: =VLOOKUP(A17,[2]CMV!$A$1:$B$2115,2,FALSE) -> MOTO PEÇAS | D17: =VLOOKUP(A17,[2]CMV!$A$1:$C$2115,3,FALSE) -> ÓLEO MOTOR | E17: =VLOOKUP(A17,[2]CMV!$A$1:$E$2115,5,FALSE) -> SAKAMOTO | G17: =VLOOKUP(A17,[2]CMV!$A$1:$F$2115,6,FALSE) -> OLEO DE MOBIL | AD17: =SUM(AE17:AG17) -> 37 | AG17: 37 | AH17: =SUM(AI17:AK17) -> 67 | AI17: 0 | AJ17: 0 | AK17: 67 | AL17: =SUM(AM17:AO17) -> 37 | AN17: 0 | AO17: 37 | AP17: =SUM(AQ17:AR17) -> 74 | AQ17: =IFERROR(VLOOKUP(A17,[1]SIIMPLES!$A$2:$F$418,6,FALSE),0) -> 74 | AR17: 0 | AS17: 51 | AT17: 0 | AU17: 0 | AV17: 51 | AY17: =IFERROR(AVERAGE(I17,N17,R17,V17,Z17,AD17,AH17,AL17,AP17,AS17,AW17,AX17),"-") -> 53.2 | BB17: =1-BA17/AY17 -> 1 | BG17: =IFERROR(BC17/AY17,"0") -> 0 | BH17: =IFERROR(IF(F17=1,IF(BC17<AY17*3,AY17*3-BC17,0),IF(BC17<AY17,AY17-BC17,0)),"") -> 53.2
A18: 2278 | B18: Sim | C18: AUTOMOTIVO | D18: Bucha Eixo Suspensão | E18: LT CORREA | F18: =IFERROR(VLOOKUP(E18,Fornecedores!$A$2:$B$2700,2,FALSE),"") -> 3 | G18: Bucha Eixo Tras Elimina Folga 47mm Peugeot 206 1999 A 2010 | I18: =SUM(J18:M18) -> 53 | J18: 3 | K18: 50 | L18: 0 | M18: 0 | N18: =SUM(O18:Q18) -> 28 | O18: 0 | P18: 28 | Q18: 0 | R18: =SUM(S18:U18) -> 56 | S18: 0 | T18: 56 | U18: 0 | V18: 90 | W18: 0 | X18: 90 | Y18: 0 | Z18: 136 | AA18: 0 | AB18: 136 | AC18: 0 | AD18: =SUM(AE18:AG18) -> 105 | AE18: 1 | AF18: 104 | AG18: 0 | AH18: =SUM(AI18:AK18) -> 104 | AI18: 0 | AJ18: 104 | AK18: 0 | AL18: =SUM(AM18:AO18) -> 94 | AN18: 94 | AO18: 0 | AP18: =SUM(AQ18:AR18) -> 70 | AQ18: =IFERROR(VLOOKUP(A18,[1]SIIMPLES!$A$2:$F$418,6,FALSE),0) -> 0 | AR18: 70 | AS18: 74 | AT18: 0 | AU18: 74 | AV18: 0 | AY18: =IFERROR(AVERAGE(I18,N18,R18,V18,Z18,AD18,AH18,AL18,AP18,AS18,AW18,AX18),"-") -> 81 | BA18: 82 | BB18: =1-BA18/AY18 -> -0.012345679 | BG18: =IFERROR(BC18/AY18,"0") -> 0 | BH18: =IFERROR(IF(F18=1,IF(BC18<AY18*3,AY18*3-BC18,0),IF(BC18<AY18,AY18-BC18,0)),"") -> 81
A19: 332057 | B19: Sim | C19: AUTOMOTIVO | D19: Bandeja | E19: SPARE | F19: =IFERROR(VLOOKUP(E19,Fornecedores!$A$2:$B$2700,2,FALSE),"") -> 2 | G19: Morceguinho Dianteiro Esquerdo Montana 2011 A 2016 | I19: =SUM(J19:M19) -> 24 | J19: 0 | K19: 24 | L19: 0 | M19: 0 | N19: =SUM(O19:Q19) -> 58 | O19: 0 | P19: 8 | Q19: 50 | R19: =SUM(S19:U19) -> 22 | S19: 0 | T19: 12 | U19: 10 | V19: 59 | W19: 0 | X19: 19 | Y19: 40 | Z19: 116 | AA19: 0 | AB19: 26 | AC19: 90 | AD19: =SUM(AE19:AG19) -> 26 | AE19: 0 | AF19: 26 | AG19: 0 | AH19: =SUM(AI19:AK19) -> 77 | AI19: 0 | AJ19: 17 | AK19: 60 | AL19: =SUM(AM19:AO19) -> 137 | AN19: 5 | AO19: 132 | AP19: =SUM(AQ19:AR19) -> 60 | AQ19: =IFERROR(VLOOKUP(A19,[1]SIIMPLES!$A$2:$F$418,6,FALSE),0) -> 51 | AR19: 9 | AS19: 53 | AT19: 0 | AU19: 3 | AV19: 50 | AY19: =IFERROR(AVERAGE(I19,N19,R19,V19,Z19,AD19,AH19,AL19,AP19,AS19,AW19,AX19),"-") -> 63.2 | BA19: 21.333333 | BB19: =1-BA19/AY19 -> 0.66244726 | BG19: =IFERROR(BC19/AY19,"0") -> 0 | BH19: =ROUND(IFERROR(IF(F19=1,IF(BC19<AY19*3,AY19*3-BC19,0),IF(BC19<AY19,AY19*0.6-BC19,0)),""),0) -> 38
A20: 332056 | B20: Sim | C20: AUTOMOTIVO | D20: Bandeja | E20: SPARE | F20: =IFERROR(VLOOKUP(E20,Fornecedores!$A$2:$B$2700,2,FALSE),"") -> 2 | G20: Morceguinho Dianteira Direita Agile 2010 A 2014 | I20: =SUM(J20:M20) -> 24 | J20: 0 | K20: 24 | L20: 0 | M20: 0 | N20: =SUM(O20:Q20) -> 58 | O20: 0 | P20: 8 | Q20: 50 | R20: =SUM(S20:U20) -> 22 | S20: 0 | T20: 12 | U20: 10 | V20: 59 | W20: 0 | X20: 19 | Y20: 40 | Z20: 116 | AA20: 0 | AB20: 26 | AC20: 90 | AD20: =SUM(AE20:AG20) -> 26 | AE20: 0 | AF20: 26 | AG20: 0 | AH20: =SUM(AI20:AK20) -> 76 | AI20: 0 | AJ20: 17 | AK20: 59 | AL20: =SUM(AM20:AO20) -> 137 | AN20: 5 | AO20: 132 | AP20: =SUM(AQ20:AR20) -> 60 | AQ20: =IFERROR(VLOOKUP(A20,[1]SIIMPLES!$A$2:$F$418,6,FALSE),0) -> 51 | AR20: 9 | AS20: 159 | AT20: 36 | AU20: 3 | AV20: 120 | AY20: =IFERROR(AVERAGE(I20,N20,R20,V20,Z20,AD20,AH20,AL20,AP20,AS20,AW20,AX20),"-") -> 73.7 | BA20: 21.5 | BB20: =IFERROR(AY20/BA20-1,"") -> 2.427907 | BG20: =IFERROR(BC20/AY20,"0") -> 0 | BH20: =IFERROR(IF(F20=1,IF(BC20<AY20*3,AY20*3-BC20,0),IF(BC20<AY20,AY20-BC20,0)),"") -> 73.7
A21: 552001 | B21: Sim | C21: AUTOMOTIVO | D21: Bandeja | E21: SPARE | F21: =IFERROR(VLOOKUP(E21,Fornecedores!$A$2:$B$2700,2,FALSE),"") -> 2 | G21: Bandeja Lado Esquerdo Peugeot 206 Todos 1999 A 2010 C Pivô | I21: =SUM(J21:M21) -> 42 | J21: 15 | K21: 16 | L21: 0 | M21: 11 | N21: =SUM(O21:Q21) -> 26 | O21: 17 | P21: 9 | Q21: 0 | R21: =SUM(S21:U21) -> 35 | S21: 12 | T21: 16 | U21: 7 | V21: 58 | W21: 22 | X21: 28 | Y21: 8 | Z21: 49 | AA21: 17 | AB21: 17 | AC21: 15 | AD21: =SUM(AE21:AG21) -> 52 | AE21: 28 | AF21: 19 | AG21: 5 | AH21: =SUM(AI21:AK21) -> 66 | AI21: 34 | AJ21: 7 | AK21: 25 | AL21: =SUM(AM21:AO21) -> 51 | AM21: 32 | AN21: 17 | AO21: 2 | AP21: =SUM(AQ21:AR21) -> 59 | AQ21: =IFERROR(VLOOKUP(A21,[1]SIIMPLES!$A$2:$F$418,6,FALSE),0) -> 43 | AR21: 16 | AS21: 12 | AT21: 7 | AU21: 3 | AV21: 2 | AY21: =IFERROR(AVERAGE(I21,N21,R21,V21,Z21,AD21,AH21,AL21,AP21,AS21,AW21,AX21),"-") -> 45 | BA21: 96.166667 | BB21: =1-BA21/AY21 -> -1.137037 | BG21: =IFERROR(BC21/AY21,"0") -> 0 | BH21: =IFERROR(IF(F21=1,IF(BC21<AY21*3,AY21*3-BC21,0),IF(BC21<AY21,AY21-BC21,0)),"") -> 45
A22: 442055 | B22: Sim | C22: AUTOMOTIVO | D22: Bandeja | E22: SPARE | F22: =IFERROR(VLOOKUP(E22,Fornecedores!$A$2:$B$2700,2,FALSE),"") -> 2 | G22: Bandeja Dianteira Ambos Lados Parati 1993 A 2008 | I22: =SUM(J22:M22) -> 43 | J22: 11 | K22: 32 | L22: 0 | M22: 0 | N22: =SUM(O22:Q22) -> 22 | O22: 0 | P22: 22 | Q22: 0 | R22: =SUM(S22:U22) -> 18 | S22: 8 | T22: 10 | U22: 0 | V22: 48 | W22: 22 | X22: 22 | Y22: 4 | Z22: 29 | AA22: 15 | AB22: 14 | AC22: 0 | AD22: =SUM(AE22:AG22) -> 41 | AE22: 11 | AF22: 10 | AG22: 20 | AH22: =SUM(AI22:AK22) -> 18 | AI22: 15 | AJ22: 0 | AK22: 3 | AL22: =SUM(AM22:AO22) -> 24 | AM22: 22 | AN22: 0 | AO22: 2 | AP22: =SUM(AQ22:AR22) -> 58 | AQ22: =IFERROR(VLOOKUP(A22,[1]SIIMPLES!$A$2:$F$418,6,FALSE),0) -> 58 | AR22: 0 | AS22: 58 | AT22: 41 | AU22: 2 | AV22: 15 | AY22: =IFERROR(AVERAGE(I22,N22,R22,V22,Z22,AD22,AH22,AL22,AP22,AS22,AW22,AX22),"-") -> 35.9 | BA22: 33 | BB22: =1-BA22/AY22 -> 0.080779944 | BF22: =SUM(BC22:BE22) -> 0 | BG22: =IFERROR(BC22/AY22,"0") -> 0 | BH22: =IFERROR(IF(F22=1,IF(BC22<AY22*3,AY22*3-BC22,0),IF(BC22<AY22,AY22-BC22,0)),"") -> 35.9
A23: 552002 | B23: Sim | C23: AUTOMOTIVO | D23: Bandeja | E23: SPARE | F23: =IFERROR(VLOOKUP(E23,Fornecedores!$A$2:$B$2700,2,FALSE),"") -> 2 | G23: Bandeja Ld Peugeot 207 Exceto Escapade 2008 Em Diante C Pivô | I23: =SUM(J23:M23) -> 56 | J23: 29 | K23: 16 | L23: 0 | M23: 11 | N23: =SUM(O23:Q23) -> 32 | O23: 24 | P23: 8 | Q23: 0 | R23: =SUM(S23:U23) -> 57 | S23: 32 | T23: 14 | U23: 11 | V23: 62 | W23: 28 | X23: 26 | Y23: 8 | Z23: 57 | AA23: 24 | AB23: 18 | AC23: 15 | AD23: =SUM(AE23:AG23) -> 44 | AE23: 20 | AF23: 19 | AG23: 5 | AH23: =SUM(AI23:AK23) -> 58 | AI23: 26 | AJ23: 7 | AK23: 25 | AL23: =SUM(AM23:AO23) -> 46 | AM23: 23 | AN23: 17 | AO23: 6 | AP23: =SUM(AQ23:AR23) -> 56 | AQ23: =IFERROR(VLOOKUP(A23,[1]SIIMPLES!$A$2:$F$418,6,FALSE),0) -> 40 | AR23: 16 | AS23: 8 | AT23: 2 | AU23: 3 | AV23: 3 | AY23: =IFERROR(AVERAGE(I23,N23,R23,V23,Z23,AD23,AH23,AL23,AP23,AS23,AW23,AX23),"-") -> 47.6 | BA23: 87.166667 | BB23: =1-BA23/AY23 -> -0.83123249
A24: T1007 | C24: AUTOMOTIVO | D24: Terminal Cabo Câmbio | E24: Importação / LT CORREA | F24: =IFERROR(VLOOKUP(E24,Fornecedores!$A$2:$B$2700,2,FALSE),"") -> 18 | G24: Terminal Conector Cabo Trambulador Celta 2005 Em Diante | I24: 71 | N24: 52 | R24: 58 | V24: 32 | Z24: 8 | AD24: 5 | AH24: =SUM(AI24:AK24) -> 27 | AI24: 7 | AJ24: 0 | AK24: 20 | AL24: =SUM(AM24:AO24) -> 34 | AM24: 1 | AN24: 33 | AO24: 0 | AP24: =SUM(AQ24:AR24) -> 55 | AQ24: =IFERROR(VLOOKUP(A24,[1]SIIMPLES!$A$2:$F$418,6,FALSE),0) -> 9 | AR24: 46 | AS24: 67 | AT24: 8 | AU24: 59 | AV24: 0 | AY24: =IFERROR(AVERAGE(I24,N24,R24,V24,Z24,AD24,AH24,AL24,AP24,AS24,AW24,AX24),"-") -> 40.9 | BA24: 55.25 | BB24: =IFERROR(AY24/BA24-1,"") -> -0.25972851 | BG24: =IFERROR(BC24/AY24,"0") -> 0 | BH24: =IFERROR(IF(F24=1,IF(BC24<AY24*3,AY24*3-BC24,0),IF(BC24<AY24,AY24-BC24,0)),"") -> 40.9
A25: 2316 | B25: Sim | C25: AUTOMOTIVO | D25: Reparo alavanta Câmbio | E25: LT CORREA | F25: =IFERROR(VLOOKUP(E25,Fornecedores!$A$2:$B$2700,2,FALSE),"") -> 3 | G25: Kit Reparo Alavanca Câmbio Trambulador Vectra 2006 Até 2011 | I25: =SUM(J25:M25) -> 75 | J25: 57 | K25: 18 | L25: 0 | M25: 0 | N25: =SUM(O25:Q25) -> 41 | O25: 40 | P25: 1 | Q25: 0 | R25: =SUM(S25:U25) -> 31 | S25: 25 | T25: 6 | U25: 0 | V25: 33 | W25: 33 | X25: 0 | Y25: 0 | Z25: 32 | AA25: 32 | AB25: 0 | AC25: 0 | AD25: =SUM(AE25:AG25) -> 33 | AE25: 33 | AF25: 0 | AG25: 0 | AH25: =SUM(AI25:AK25) -> 7 | AI25: 7 | AJ25: 0 | AK25: 0 | AL25: =SUM(AM25:AO25) -> 28 | AM25: 26 | AN25: 2 | AO25: 0 | AP25: =SUM(AQ25:AR25) -> 50 | AQ25: =IFERROR(VLOOKUP(A25,[1]SIIMPLES!$A$2:$F$418,6,FALSE),0) -> 39 | AR25: 11 | AS25: 4 | AT25: 1 | AU25: 3 | AV25: 0 | AY25: =IFERROR(AVERAGE(I25,N25,R25,V25,Z25,AD25,AH25,AL25,AP25,AS25,AW25,AX25),"-") -> 33.4 | BA25: 83.166667 | BB25: =1-BA25/AY25 -> -1.49002 | BG25: =IFERROR(BC25/AY25,"0") -> 0 | BH25: =IFERROR(IF(F25=1,IF(BC25<AY25*3,AY25*3-BC25,0),IF(BC25<AY25,AY25-BC25,0)),"") -> 33.4
A26: NZT311396 | B26: Sim | C26: AUTOMOTIVO | D26: Rolamento Roda | E26: Importação / Polo | F26: =IFERROR(VLOOKUP(E26,Fornecedores!$A$2:$B$2700,2,FALSE),"") | G26: Rolamento Da Roda Dianteira Sem Abs Kadett 89 A 97 | I26: =SUM(J26:M26) -> 358 | J26: 0 | K26: 58 | L26: 300 | M26: 0 | N26: =SUM(O26:Q26) -> 141 | O26: 3 | P26: 38 | Q26: 100 | R26: =SUM(S26:U26) -> 162 | S26: 4 | T26: 58 | U26: 100 | V26: 193 | W26: 7 | X26: 86 | Y26: 100 | Z26: 104 | AA26: 4 | AB26: 100 | AC26: 0 | AD26: =SUM(AE26:AG26) -> 409 | AE26: 1 | AF26: 108 | AG26: 300 | AH26: =SUM(AI26:AK26) -> 60 | AI26: 0 | AJ26: 60 | AK26: 0 | AL26: =SUM(AM26:AO26) -> 59 | AM26: 3 | AN26: 56 | AO26: 0 | AP26: =SUM(AQ26:AR26) -> 50 | AQ26: =IFERROR(VLOOKUP(A26,[1]SIIMPLES!$A$2:$F$418,6,FALSE),0) -> 0 | AR26: 50 | AS26: 20 | AT26: 0 | AU26: 20 | AV26: 0 | AY26: =IFERROR(AVERAGE(I26,N26,R26,V26,Z26,AD26,AH26,AL26,AP26,AS26,AW26,AX26),"-") -> 155.6 | BA26: 105.33333 | BB26: =1-BA26/AY26 -> 0.32305056 | BG26: =IFERROR(BC26/AY26,"0") -> 0 | BH26: =ROUND(IFERROR(IF(F26=1,IF(BC26<AY26*3,AY26*3-BC26,0),IF(BC26<AY26,AY26*0.6-BC26,0)),""),0) -> 93
A27: FTK11057 | B27: Sim | C27: AUTOMOTIVO | D27: Pivô | E27: SPARE | F27: =IFERROR(VLOOKUP(E27,Fornecedores!$A$2:$B$2700,2,FALSE),"") -> 2 | G27: Pivô Lado Esquerdo Gol G6 2012 Em Diante | I27: =SUM(J27:M27) -> 7 | J27: 2 | K27: 5 | L27: 0 | M27: 0 | N27: =SUM(O27:Q27) -> 11 | O27: 2 | P27: 9 | Q27: 0 | R27: =SUM(S27:U27) -> 15 | S27: 2 | T27: 13 | U27: 0 | V27: 17 | W27: 1 | X27: 16 | Y27: 0 | Z27: 2 | AA27: 1 | AB27: 1 | AC27: 0 | AD27: =SUM(AE27:AG27) -> 33 | AE27: 3 | AF27: 30 | AG27: 0 | AH27: =SUM(AI27:AK27) -> 35 | AI27: 4 | AJ27: 31 | AK27: 0 | AL27: =SUM(AM27:AO27) -> 36 | AN27: 36 | AO27: 0 | AP27: =SUM(AQ27:AR27) -> 48 | AQ27: =IFERROR(VLOOKUP(A27,[1]SIIMPLES!$A$2:$F$418,6,FALSE),0) -> 3 | AR27: 45 | AS27: 50 | AT27: 0 | AU27: 50 | AV27: 0 | AY27: =IFERROR(AVERAGE(I27,N27,R27,V27,Z27,AD27,AH27,AL27,AP27,AS27,AW27,AX27),"-") -> 25.4 | BA27: 4.8333333 | BB27: =IFERROR(AY27/BA27-1,"") -> 4.2551724
A28: 142401 | C28: MOTO PEÇAS | D28: ÓLEO MOTOR | E28: Outros | G28: OLEO SB 5W30 CARRO | AL28: =SUM(AM28:AO28) -> 76 | AO28: 76 | AP28: =SUM(AQ28:AR28) -> 48 | AQ28: =IFERROR(VLOOKUP(A28,[1]SIIMPLES!$A$2:$F$418,6,FALSE),0) -> 48 | AR28: 0 | AS28: 0 | AT28: 0 | AU28: 0 | AV28: 0 | BB28: =IFERROR(AY28/BA28-1,"") | BG28: =IFERROR(BC28/AY28,"0") -> 0 | BH28: =IFERROR(IF(F28=1,IF(BC28<AY28*3,AY28*3-BC28,0),IF(BC28<AY28,AY28-BC28,0)),"") -> 0
A29: 23079 | B29: Sim | C29: AUTOMOTIVO | D29: Pino de Porta | E29: MultiKit | F29: =IFERROR(VLOOKUP(E29,Fornecedores!$A$2:$B$2700,2,FALSE),"") -> 4 | G29: Pino Da Dobradiça Da Porta Blazer 1996 A 2011 | I29: =SUM(J29:M29) -> 38 | J29: 8 | K29: 30 | L29: 0 | M29: 0 | N29: =SUM(O29:Q29) -> 82 | O29: 6 | P29: 76 | Q29: 0 | R29: =SUM(S29:U29) -> 50 | S29: 0 | T29: 50 | U29: 0 | V29: 66 | W29: 0 | X29: 66 | Y29: 0 | Z29: 73 | AA29: 1 | AB29: 72 | AC29: 0 | AD29: =SUM(AE29:AG29) -> 114 | AE29: 0 | AF29: 114 | AG29: 0 | AH29: =SUM(AI29:AK29) -> 95 | AI29: 1 | AJ29: 94 | AK29: 0 | AL29: =SUM(AM29:AO29) -> 66 | AN29: 66 | AO29: 0 | AP29: =SUM(AQ29:AR29) -> 46 | AQ29: =IFERROR(VLOOKUP(A29,[1]SIIMPLES!$A$2:$F$418,6,FALSE),0) -> 0 | AR29: 46 | AS29: 36 | AT29: 0 | AU29: 36 | AV29: 0 | AY29: =IFERROR(AVERAGE(I29,N29,R29,V29,Z29,AD29,AH29,AL29,AP29,AS29,AW29,AX29),"-") -> 66.6 | BA29: 89.5 | BB29: =IFERROR(AY29/BA29-1,"") -> -0.25586592 | BG29: =IFERROR(BC29/AY29,"0") -> 0 | BH29: =ROUND(IFERROR(IF(F29=1,IF(BC29<AY29*3,AY29*3-BC29,0),IF(BC29<AY29,AY29*0.6-BC29,0)),""),0) -> 40
A30: FTK11056 | B30: Sim | C30: AUTOMOTIVO | D30: Pivô | E30: SPARE | F30: =IFERROR(VLOOKUP(E30,Fornecedores!$A$2:$B$2700,2,FALSE),"") -> 2 | G30: Pivô Lado Direito Crossfox 2014 Em Diante | I30: =SUM(J30:M30) -> 5 | J30: 0 | K30: 5 | L30: 0 | M30: 0 | N30: =SUM(O30:Q30) -> 11 | O30: 2 | P30: 9 | Q30: 0 | R30: =SUM(S30:U30) -> 14 | S30: 1 | T30: 13 | U30: 0 | V30: 18 | W30: 2 | X30: 16 | Y30: 0 | Z30: 2 | AA30: 1 | AB30: 1 | AC30: 0 | AD30: =SUM(AE30:AG30) -> 30 | AE30: 0 | AF30: 30 | AG30: 0 | AH30: =SUM(AI30:AK30) -> 31 | AI30: 0 | AJ30: 31 | AK30: 0 | AL30: =SUM(AM30:AO30) -> 36 | AN30: 36 | AO30: 0 | AP30: =SUM(AQ30:AR30) -> 45 | AQ30: =IFERROR(VLOOKUP(A30,[1]SIIMPLES!$A$2:$F$418,6,FALSE),0) -> 0 | AR30: 45 | AS30: 55 | AT30: 5 | AU30: 50 | AV30: 0 | AY30: =IFERROR(AVERAGE(I30,N30,R30,V30,Z30,AD30,AH30,AL30,AP30,AS30,AW30,AX30),"-") -> 24.7 | BA30: 6.1666667 | BB30: =1-BA30/AY30 -> 0.75033738 | BG30: =IFERROR(BC30/AY30,"0") -> 0 | BH30: =ROUND(IFERROR(IF(F30=1,IF(BC30<AY30*3,AY30*3-BC30,0),IF(BC30<AY30,AY30*0.6-BC30,0)),""),0) -> 15
A31: PG001A | B31: Sim | C31: AUTOMOTIVO | D31: Rolamento Eixo | E31: Importação | F31: =IFERROR(VLOOKUP(E31,Fornecedores!$A$2:$B$2700,2,FALSE),"") -> 1 | G31: Kit De Rolamento Eixo Traseiro 207 Passion Com Barra 50mm | I31: =SUM(J31:M31) -> 60 | J31: 0 | K31: 60 | L31: 0 | M31: 0 | N31: =SUM(O31:Q31) -> 36 | O31: 2 | P31: 34 | Q31: 0 | R31: =SUM(S31:U31) -> 48 | S31: 0 | T31: 42 | U31: 6 | V31: 84 | W31: 8 | X31: 56 | Y31: 20 | Z31: 76 | AA31: 0 | AB31: 72 | AC31: 4 | AD31: =SUM(AE31:AG31) -> 76 | AE31: 0 | AF31: 72 | AG31: 4 | AH31: =SUM(AI31:AK31) -> 54 | AI31: 4 | AJ31: 50 | AK31: 0 | AL31: =SUM(AM31:AO31) -> 63 | AM31: 3 | AN31: 58 | AO31: 2 | AP31: =SUM(AQ31:AR31) -> 42 | AQ31: =IFERROR(VLOOKUP(A31,[1]SIIMPLES!$A$2:$F$418,6,FALSE),0) -> 2 | AR31: 40 | AS31: 42 | AT31: 0 | AU31: 42 | AV31: 0 | AY31: =IFERROR(AVERAGE(I31,N31,R31,V31,Z31,AD31,AH31,AL31,AP31,AS31,AW31,AX31),"-") -> 58.1 | BA31: 77.166667 | BB31: =IFERROR(AY31/BA31-1,"") -> -0.24708423 | BG31: =IFERROR(BC31/AY31,"0") -> 0 | BH31: =ROUND(IFERROR(IF(F31=1,IF(BC31<AY31*3,AY31*3-BC31,0),IF(BC31<AY31,AY31*0.6-BC31,0)),""),0) -> 174
A32: 442090 | B32: Sim | C32: AUTOMOTIVO | D32: Bandeja | E32: SPARE | F32: =IFERROR(VLOOKUP(E32,Fornecedores!$A$2:$B$2700,2,FALSE),"") -> 2 | G32: Bandeja Sem Pivô Lado Esquerdo Saveiro G6 2012 Em Diante | I32: =SUM(J32:M32) -> 10 | J32: 5 | K32: 5 | L32: 0 | M32: 0 | N32: =SUM(O32:Q32) -> 10 | O32: 1 | P32: 9 | Q32: 0 | R32: =SUM(S32:U32) -> 10 | S32: 0 | T32: 10 | U32: 0 | V32: 20 | W32: 0 | X32: 15 | Y32: 5 | Z32: 5 | AA32: 2 | AB32: 3 | AC32: 0 | AD32: =SUM(AE32:AG32) -> 59 | AE32: 0 | AF32: 29 | AG32: 30 | AH32: =SUM(AI32:AK32) -> 20 | AI32: 0 | AJ32: 20 | AK32: 0 | AL32: =SUM(AM32:AO32) -> 36 | AN32: 30 | AO32: 6 | AP32: =SUM(AQ32:AR32) -> 40 | AQ32: =IFERROR(VLOOKUP(A32,[1]SIIMPLES!$A$2:$F$418,6,FALSE),0) -> 0 | AR32: 40 | AS32: 48 | AT32: 0 | AU32: 48 | AV32: 0 | AY32: =IFERROR(AVERAGE(I32,N32,R32,V32,Z32,AD32,AH32,AL32,AP32,AS32,AW32,AX32),"-") -> 25.8 | BA32: 5.5 | BB32: =IFERROR(AY32/BA32-1,"") -> 3.6909091 | BG32: =IFERROR(BC32/AY32,"0") -> 0 | BH32: =ROUND(IFERROR(IF(F32=1,IF(BC32<AY32*3,AY32*3-BC32,0),IF(BC32<AY32,AY32*0.6-BC32,0)),""),0) -> 15
A33: 442091 | B33: Sim | C33: AUTOMOTIVO | D33: Bandeja | E33: SPARE | F33: =IFERROR(VLOOKUP(E33,Fornecedores!$A$2:$B$2700,2,FALSE),"") -> 2 | G33: Bandeja Sem Pivô Lado Direito Gol G6 2012 Em Diante | I33: =SUM(J33:M33) -> 7 | J33: 0 | K33: 7 | L33: 0 | M33: 0 | N33: =SUM(O33:Q33) -> 11 | O33: 0 | P33: 11 | Q33: 0 | R33: =SUM(S33:U33) -> 10 | S33: 0 | T33: 10 | U33: 0 | V33: 20 | W33: 0 | X33: 15 | Y33: 5 | Z33: 5 | AA33: 2 | AB33: 3 | AC33: 0 | AD33: =SUM(AE33:AG33) -> 59 | AE33: 0 | AF33: 29 | AG33: 30 | AH33: =SUM(AI33:AK33) -> 20 | AI33: 0 | AJ33: 20 | AK33: 0 | AL33: =SUM(AM33:AO33) -> 36 | AN33: 30 | AO33: 6 | AP33: =SUM(AQ33:AR33) -> 40 | AQ33: =IFERROR(VLOOKUP(A33,[1]SIIMPLES!$A$2:$F$418,6,FALSE),0) -> 0 | AR33: 40 | AS33: 50 | AT33: 2 | AU33: 48 | AV33: 0 | AY33: =IFERROR(AVERAGE(I33,N33,R33,V33,Z33,AD33,AH33,AL33,AP33,AS33,AW33,AX33),"-") -> 25.8 | BA33: 5.6666667 | BB33: =IFERROR(AY33/BA33-1,"") -> 3.5529412 | BG33: =IFERROR(BC33/AY33,"0") -> 0 | BH33: =IFERROR(IF(F33=1,IF(BC33<AY33*3,AY33*3-BC33,0),IF(BC33<AY33,AY33-BC33,0)),"") -> 25.8
A34: 28006 | B34: Sim | C34: AUTOMOTIVO | D34: Pino de Freio | E34: MultiKit | F34: =IFERROR(VLOOKUP(E34,Fornecedores!$A$2:$B$2700,2,FALSE),"") -> 4 | G34: Reparo Pino Guia Pinça De Freio Dianteiro Nissan Versa | I34: =SUM(J34:M34) -> 26 | J34: 0 | K34: 26 | L34: 0 | M34: 0 | N34: =SUM(O34:Q34) -> 36 | O34: 6 | P34: 30 | Q34: 0 | R34: =SUM(S34:U34) -> 9 | S34: 1 | T34: 6 | U34: 2 | V34: 29 | W34: 9 | X34: 20 | Y34: 0 | Z34: 34 | AA34: 2 | AB34: 32 | AC34: 0 | AD34: =SUM(AE34:AG34) -> 43 | AE34: 3 | AF34: 40 | AG34: 0 | AH34: =SUM(AI34:AK34) -> 27 | AI34: 1 | AJ34: 26 | AK34: 0 | AL34: =SUM(AM34:AO34) -> 12 | AM34: 2 | AN34: 10 | AO34: 0 | AP34: =SUM(AQ34:AR34) -> 39 | AQ34: =IFERROR(VLOOKUP(A34,[1]SIIMPLES!$A$2:$F$418,6,FALSE),0) -> 9 | AR34: 30 | AS34: 45 | AT34: 1 | AU34: 44 | AV34: 0 | AY34: =IFERROR(AVERAGE(I34,N34,R34,V34,Z34,AD34,AH34,AL34,AP34,AS34,AW34,AX34),"-") -> 30 | BA34: 53.666667 | BB34: =IFERROR(AY34/BA34-1,"") -> -0.44099379
A35: 112001 | B35: Sim | C35: AUTOMOTIVO | D35: Bandeja | E35: SPARE | F35: =IFERROR(VLOOKUP(E35,Fornecedores!$A$2:$B$2700,2,FALSE),"") -> 2 | G35: Bandeja Traseira Uno Cs S Sx 1984 A 1996 | I35: =SUM(J35:M35) -> 10 | J35: 2 | K35: 8 | L35: 0 | M35: 0 | N35: =SUM(O35:Q35) -> 6 | O35: 0 | P35: 6 | Q35: 0 | R35: =SUM(S35:U35) -> 11 | S35: 3 | T35: 4 | U35: 4 | V35: 19 | W35: 3 | X35: 16 | Y35: 0 | Z35: 33 | AA35: 1 | AB35: 22 | AC35: 10 | AD35: =SUM(AE35:AG35) -> 28 | AE35: 0 | AF35: 28 | AG35: 0 | AH35: =SUM(AI35:AK35) -> 25 | AI35: 5 | AJ35: 20 | AK35: 0 | AL35: =SUM(AM35:AO35) -> 37 | AM35: 5 | AN35: 32 | AO35: 0 | AP35: =SUM(AQ35:AR35) -> 39 | AQ35: =IFERROR(VLOOKUP(A35,[1]SIIMPLES!$A$2:$F$418,6,FALSE),0) -> 3 | AR35: 36 | AS35: 64 | AT35: 20 | AU35: 42 | AV35: 2 | AY35: =IFERROR(AVERAGE(I35,N35,R35,V35,Z35,AD35,AH35,AL35,AP35,AS35,AW35,AX35),"-") -> 27.2 | BA35: 14.333333 | BB35: =IFERROR(AY35/BA35-1,"") -> 0.89767442 | BF35: =SUM(BC35:BE35) -> 0 | BG35: =IFERROR(BC35/AY35,"0") -> 0 | BH35: =IFERROR(IF(F35=1,IF(BC35<AY35*3,AY35*3-BC35,0),IF(BC35<AY35,AY35-BC35,0)),"") -> 27.2
A36: FD001 | B36: Sim | C36: AUTOMOTIVO | D36: Rolamento Roda | E36: Importação | F36: =IFERROR(VLOOKUP(E36,Fornecedores!$A$2:$B$2700,2,FALSE),"") -> 1 | G36: Kit Rolamento Roda Traseira Ford Verona 1993 1994 1995 1996. | I36: =SUM(J36:M36) -> 85 | J36: 37 | K36: 48 | L36: 0 | M36: 0 | N36: =SUM(O36:Q36) -> 173 | O36: 35 | P36: 38 | Q36: 100 | R36: =SUM(S36:U36) -> 56 | S36: 26 | T36: 30 | U36: 0 | V36: 106 | W36: 40 | X36: 66 | Y36: 0 | Z36: 52 | AA36: 14 | AB36: 38 | AC36: 0 | AD36: =SUM(AE36:AG36) -> 81 | AE36: 21 | AF36: 50 | AG36: 10 | AH36: =SUM(AI36:AK36) -> 60 | AI36: 22 | AJ36: 38 | AK36: 0 | AL36: =SUM(AM36:AO36) -> 123 | AM36: 41 | AN36: 32 | AO36: 50 | AP36: =SUM(AQ36:AR36) -> 39 | AQ36: =IFERROR(VLOOKUP(A36,[1]SIIMPLES!$A$2:$F$418,6,FALSE),0) -> 13 | AR36: 26 | AS36: 39 | AT36: 11 | AU36: 28 | AV36: 0 | AY36: =IFERROR(AVERAGE(I36,N36,R36,V36,Z36,AD36,AH36,AL36,AP36,AS36,AW36,AX36),"-") -> 81.4 | BA36: 151.16667 | BB36: =IFERROR(AY36/BA36-1,"") -> -0.4615215 | BG36: =IFERROR(BC36/AY36,"0") -> 0 | BH36: =IFERROR(IF(F36=1,IF(BC36<AY36*3,AY36*3-BC36,0),IF(BC36<AY36,AY36-BC36,0)),"") -> 244.2
A37: 13125 | B37: Sim | C37: AUTOMOTIVO | D37: Pino de Freio | E37: MultiKit | F37: =IFERROR(VLOOKUP(E37,Fornecedores!$A$2:$B$2700,2,FALSE),"") -> 4 | G37: Kit Guia Pinça De Freio Sonic Lt Flex 1.6man 2013 | I37: =SUM(J37:M37) -> 61 | J37: 25 | K37: 36 | L37: 0 | M37: 0 | N37: =SUM(O37:Q37) -> 54 | O37: 16 | P37: 38 | Q37: 0 | R37: =SUM(S37:U37) -> 39 | S37: 19 | T37: 20 | U37: 0 | V37: 69 | W37: 31 | X37: 38 | Y37: 0 | Z37: 43 | AA37: 15 | AB37: 28 | AC37: 0 | AD37: =SUM(AE37:AG37) -> 41 | AE37: 15 | AF37: 26 | AG37: 0 | AH37: =SUM(AI37:AK37) -> 25 | AI37: 17 | AJ37: 8 | AK37: 0 | AL37: =SUM(AM37:AO37) -> 32 | AM37: 4 | AN37: 28 | AO37: 0 | AP37: =SUM(AQ37:AR37) -> 37 | AQ37: =IFERROR(VLOOKUP(A37,[1]SIIMPLES!$A$2:$F$418,6,FALSE),0) -> 11 | AR37: 26 | AS37: 84 | AT37: 34 | AU37: 50 | AV37: 0 | AY37: =IFERROR(AVERAGE(I37,N37,R37,V37,Z37,AD37,AH37,AL37,AP37,AS37,AW37,AX37),"-") -> 48.5 | BA37: 63 | BB37: =1-BA37/AY37 -> -0.29896907 | BG37: =IFERROR(BC37/AY37,"0") -> 0 | BH37: =IFERROR(IF(F37=1,IF(BC37<AY37*3,AY37*3-BC37,0),IF(BC37<AY37,AY37-BC37,0)),"") -> 48.5
A38: LT5609 | B38: Sim | C38: AUTOMOTIVO | D38: Reparo alavanta Câmbio | E38: LT CORREA | F38: =IFERROR(VLOOKUP(E38,Fornecedores!$A$2:$B$2700,2,FALSE),"") -> 3 | G38: Kit Reparo Terminal Cabo Engate Seleção Nissan Versa | I38: =SUM(J38:M38) -> 34 | J38: 33 | K38: 0 | L38: 0 | M38: 1 | N38: =SUM(O38:Q38) -> 35 | O38: 35 | P38: 0 | Q38: 0 | R38: =SUM(S38:U38) -> 51 | S38: 47 | T38: 0 | U38: 4 | V38: 48 | W38: 47 | X38: 0 | Y38: 1 | Z38: 42 | AA38: 42 | AB38: 0 | AC38: 0 | AD38: =SUM(AE38:AG38) -> 31 | AE38: 31 | AF38: 0 | AG38: 0 | AH38: =SUM(AI38:AK38) -> 25 | AI38: 25 | AJ38: 0 | AK38: 0 | AL38: =SUM(AM38:AO38) -> 58 | AM38: 58 | AN38: 0 | AO38: 0 | AP38: =SUM(AQ38:AR38) -> 37 | AQ38: =IFERROR(VLOOKUP(A38,[1]SIIMPLES!$A$2:$F$418,6,FALSE),0) -> 37 | AR38: 0 | AS38: 25 | AT38: 25 | AU38: 0 | AV38: 0 | AY38: =IFERROR(AVERAGE(I38,N38,R38,V38,Z38,AD38,AH38,AL38,AP38,AS38,AW38,AX38),"-") -> 38.6 | BA38: 77.833333 | BB38: =IFERROR(AY38/BA38-1,"") -> -0.50406852 | BG38: =IFERROR(BC38/AY38,"0") -> 0 | BH38: =IFERROR(IF(F38=1,IF(BC38<AY38*3,AY38*3-BC38,0),IF(BC38<AY38,AY38-BC38,0)),"") -> 38.6
A39: 2374 | C39: AUTOMOTIVO | D39: Suporte Radiador | E39: LT CORREA | F39: =IFERROR(VLOOKUP(E39,Fornecedores!$A$2:$B$2700,2,FALSE),"") -> 3 | G39: Kit Suporte Coxim Superior Do Radiador Cobalt 2012 Em Diante | I39: =SUM(J39:M39) -> 0 | N39: =SUM(O39:Q39) -> 0 | R39: =SUM(S39:U39) -> 5 | S39: 5 | T39: 0 | V39: 19 | W39: 19 | X39: 0 | Y39: 0 | Z39: 20 | AA39: 20 | AB39: 0 | AC39: 0 | AD39: =SUM(AE39:AG39) -> 34 | AE39: 34 | AF39: 0 | AG39: 0 | AH39: =SUM(AI39:AK39) -> 32 | AI39: 32 | AJ39: 0 | AK39: 0 | AL39: =SUM(AM39:AO39) -> 36 | AM39: 36 | AN39: 0 | AO39: 0 | AP39: =SUM(AQ39:AR39) -> 36 | AQ39: =IFERROR(VLOOKUP(A39,[1]SIIMPLES!$A$2:$F$418,6,FALSE),0) -> 36 | AR39: 0 | AS39: 43 | AT39: 43 | AU39: 0 | AV39: 0 | AY39: =IFERROR(AVERAGE(I39,N39,R39,V39,Z39,AD39,AH39,AL39,AP39,AS39,AW39,AX39),"-") -> 22.5 | BB39: =1-BA39/AY39 -> #VALUE! | BG39: =IFERROR(BC39/AY39,"0") -> 0 | BH39: =IFERROR(IF(F39=1,IF(BC39<AY39*3,AY39*3-BC39,0),IF(BC39<AY39,AY39-BC39,0)),"") -> 22.5
A40: 5554 | B40: Sim | C40: AUTOMOTIVO | D40: Terminal Cabo Câmbio | E40: LT CORREA | F40: =IFERROR(VLOOKUP(E40,Fornecedores!$A$2:$B$2700,2,FALSE),"") -> 3 | G40: Terminal Cabo De Engate Audi A3 2003 | I40: =SUM(J40:M40) -> 47 | J40: 47 | K40: 0 | L40: 0 | M40: 0 | N40: =SUM(O40:Q40) -> 23 | O40: 23 | P40: 0 | Q40: 0 | R40: =SUM(S40:U40) -> 35 | S40: 35 | T40: 0 | U40: 0 | V40: 33 | W40: 33 | X40: 0 | Y40: 0 | Z40: 19 | AA40: 19 | AB40: 0 | AC40: 0 | AD40: =SUM(AE40:AG40) -> 47 | AE40: 47 | AF40: 0 | AG40: 0 | AH40: =SUM(AI40:AK40) -> 32 | AI40: 32 | AJ40: 0 | AK40: 0 | AL40: =SUM(AM40:AO40) -> 43 | AM40: 43 | AN40: 0 | AO40: 0 | AP40: =SUM(AQ40:AR40) -> 35 | AQ40: =IFERROR(VLOOKUP(A40,[1]SIIMPLES!$A$2:$F$418,6,FALSE),0) -> 35 | AR40: 0 | AS40: 0 | AT40: 0 | AU40: 0 | AV40: 0 | AY40: =IFERROR(AVERAGE(I40,N40,R40,V40,Z40,AD40,AH40,AL40,AP40,AS40,AW40,AX40),"-") -> 31.4 | BA40: 51.333333 | BB40: =IFERROR(AY40/BA40-1,"") -> -0.38831169 | BG40: =IFERROR(BC40/AY40,"0") -> 0 | BH40: =IFERROR(IF(F40=1,IF(BC40<AY40*3,AY40*3-BC40,0),IF(BC40<AY40,AY40-BC40,0)),"") -> 31.4
...

Sheet Curva ABC moto
F1: 18 | G1: 5 | H1: 38 | I1: =IFERROR(AVERAGE(F1:H1,),"-") -> 15.25 | J1: =SUBTOTAL(9,J3:J8495) -> 35.5
A2: CURVA ABC | B2: SKU | C2: Categoria | D2: FORNECEDOR | E2: Descrição / Aplicação | F2: Janeiro | G2: Fevereiro | H2: Março | I2: MÉDIA 2024 | J2: MÉDIA 2023
A3: A | B3: CCE0048 | C3: Cabo Embreagem moto | D3: POLO | E3: CCE0048 CABO EMBREAGEM HONDA HONDA CG 125 FAN ES/KS 09/108,63 | H3: 3 | I3: =IFERROR(AVERAGE(F3:H3,),"-") -> 1.5 | J3: =IFERROR(VLOOKUP(B3,'[5]2023'!$A$3:$AK$1248,37,FALSE),"")
A4: A | B4: YBR 125 Velocímetro | C4: Cabo velocímetro Moto | D4: Importação | E4: Cabo De Velocímetro Yamaha Ybr 125 2003 2004 2005 | F4: 14 | G4: 0 | H4: 0 | I4: =IFERROR(AVERAGE(F4:H4,),"-") -> 3.5 | J4: =IFERROR(VLOOKUP(B4,'[5]2023'!$A$3:$AK$1248,37,FALSE),"") -> 10.666667
A5: A | B5: FTK-CCA0036 | C5: Cabo Acelerador Moto | D5: POLO | E5: Cabo Acelerador Nxr 150 Bros Ks 2009 A 2012 | F5: 2 | G5: 0 | H5: 0 | I5: =IFERROR(AVERAGE(F5:H5,),"-") -> 0.5 | J5: =IFERROR(VLOOKUP(B5,'[5]2023'!$A$3:$AK$1248,37,FALSE),"") -> 7
A6: A | B6: CCA0041 | C6: Cabo Acelerador Moto | D6: POLO | E6: CCA0041 CABO ACELERADOR HONDA (B) TITAN FAN 160 16> | F6: 0 | G6: 0 | H6: 6 | I6: =IFERROR(AVERAGE(F6:H6,),"-") -> 1.5 | J6: =IFERROR(VLOOKUP(B6,'[5]2023'!$A$3:$AK$1248,37,FALSE),"") -> 0
A7: A | B7: CCE0054 | C7: Cabo Embreagem Moto | D7: POLO | E7: CCE0054 CABO EMBREAGEM YAMAHA YBR 125 FACTOR ED/EK 09> | F7: 0 | G7: 0 | H7: 5 | I7: =IFERROR(AVERAGE(F7:H7,),"-") -> 1.25 | J7: =IFERROR(VLOOKUP(B7,'[5]2023'!$A$3:$AK$1248,37,FALSE),"") -> 1.6666667
A8: B | B8: CCA0006 | C8: Cabo Acelerador Moto | D8: POLO | E8: CCA0006 CABO ACELERADOR YAMAHA YBR 125 2002/... YBR ED 2006/2008 | F8: 0 | G8: 0 | H8: 5 | I8: =IFERROR(AVERAGE(F8:H8,),"-") -> 1.25 | J8: =IFERROR(VLOOKUP(B8,'[5]2023'!$A$3:$AK$1248,37,FALSE),"") -> 0
A9: B | B9: CCA0040 | C9: Cabo Acelerador Moto | D9: POLO | E9: CCA0040 CABO ACELERADOR HONDA (A) TITAN FAN 160 16> | F9: 0 | G9: 0 | H9: 5 | I9: =IFERROR(AVERAGE(F9:H9,),"-") -> 1.25 | J9: =IFERROR(VLOOKUP(B9,'[5]2023'!$A$3:$AK$1248,37,FALSE),"") -> 0
A10: B | B10: CCV0029 | C10: Cabo velocímetro Moto | D10: POLO | E10: CCV0029 CABO VELOCIMETRO YAMAHA YBR 2002/... | F10: 0 | G10: 0 | H10: 5 | I10: =IFERROR(AVERAGE(F10:H10,),"-") -> 1.25 | J10: =IFERROR(VLOOKUP(B10,'[5]2023'!$A$3:$AK$1248,37,FALSE),"") -> 0
A11: B | B11: FTK-CCV0062 | C11: Cabo velocímetro Moto | D11: POLO | E11: CCV0062 CABO VELOCIMETRO HONDA NXR 150 BROS ESD 08/12 ES/KS 09/127,5 | F11: 0 | G11: 2 | H11: 0 | I11: =IFERROR(AVERAGE(F11:H11,),"-") -> 0.5 | J11: =IFERROR(VLOOKUP(B11,'[5]2023'!$A$3:$AK$1248,37,FALSE),"")
A12: B | B12: FTK-CCA0035 | C12: Cabo Acelerador Moto | D12: POLO | E12: CCA0035 CABO ACELERADOR HONDA CG 150 TITAN MIX ESD 2009/... | F12: 0 | G12: 0 | H12: 1 | I12: =IFERROR(AVERAGE(F12:H12,),"-") -> 0.25 | J12: =IFERROR(VLOOKUP(B12,'[5]2023'!$A$3:$AK$1248,37,FALSE),"")
A13: B | B13: FTK-CCA0043 | C13: Cabo Acelerador Moto | D13: POLO | E13: CCA0043 CABO ACELERADOR HONDA CG 125 FAN / CARGO KS / FAN 14> | F13: 0 | G13: 0 | H13: 1 | I13: =IFERROR(AVERAGE(F13:H13,),"-") -> 0.25 | J13: =IFERROR(VLOOKUP(B13,'[5]2023'!$A$3:$AK$1248,37,FALSE),"")
A14: B | B14: FTK-CCE0048 | C14: Cabo Embreagem moto | D14: POLO | E14: CCE0048 CABO EMBREAGEM HONDA HONDA CG 125 FAN ES/KS 09/108,63 | F14: 0 | G14: 1 | H14: 0 | I14: =IFERROR(AVERAGE(F14:H14,),"-") -> 0.25 | J14: =IFERROR(VLOOKUP(B14,'[5]2023'!$A$3:$AK$1248,37,FALSE),"")
A15: B | B15: 880409 | C15: Cabo velocímetro Moto | D15: Importação | E15: CABO DE VELOCÍMETRO CG 150 FAN ESI 2010 EM DIANTE | F15: 1 | G15: 1 | H15: 1 | I15: =IFERROR(AVERAGE(F15:H15,),"-") -> 0.75 | J15: =IFERROR(VLOOKUP(B15,'[5]2023'!$A$3:$AK$1248,37,FALSE),"") -> 0.5
A16: B | B16: CCE0043 | C16: Cabo Embreagem moto | D16: POLO | F16: 0 | G16: 0 | H16: 4 | I16: =IFERROR(AVERAGE(F16:H16,),"-") -> 1 | J16: =IFERROR(VLOOKUP(B16,'[5]2023'!$A$3:$AK$1248,37,FALSE),"") -> 0
A17: B | B17: FTK-CCV0061 | C17: Cabo velocímetro Moto | D17: POLO | E17: CABO DE VELOCÍMETRO BIZ 125 2008 a 2013 | F17: 1 | G17: 1 | H17: 2 | I17: =IFERROR(AVERAGE(F17:H17,),"-") -> 1 | J17: =IFERROR(VLOOKUP(B17,'[5]2023'!$A$3:$AK$1248,37,FALSE),"") -> 0
A18: C | B18: 330254 | C18: Cabo velocímetro Moto | D18: Importação | E18: CABO DE VELOCÍMETRO CG 125 FAN | F18: 0 | G18: 0 | H18: 0 | I18: =IFERROR(AVERAGE(F18:H18,),"-") -> 0 | J18: =IFERROR(VLOOKUP(B18,'[5]2023'!$A$3:$AK$1248,37,FALSE),"")
A19: C | B19: 330351 | C19: Cabo Acelerador Moto | D19: importação | E19: CABO DE ACELERADOR NXR 150 BROS ES | F19: 0 | G19: 0 | H19: 0 | I19: =IFERROR(AVERAGE(F19:H19,),"-") -> 0 | J19: =IFERROR(VLOOKUP(B19,'[5]2023'!$A$3:$AK$1248,37,FALSE),"")
A20: C | B20: CCA0031 | C20: Cabo Acelerador Moto | D20: POLO | E20: CCA0031 CABO ACELERADOR HONDA CG 150 TITAN 08> | F20: 0 | G20: 0 | H20: 0 | I20: =IFERROR(AVERAGE(F20:H20,),"-") -> 0 | J20: =IFERROR(VLOOKUP(B20,'[5]2023'!$A$3:$AK$1248,37,FALSE),"") -> 3.3333333
A21: C | B21: CCE0045 | C21: Cabo Embreagem Moto | D21: POLO | E21: CCE0045 CABO EMBREAGEM HONDA CG 150 TITAN ES/KS 08> | F21: 0 | G21: 0 | H21: 0 | I21: =IFERROR(AVERAGE(F21:H21,),"-") -> 0 | J21: =IFERROR(VLOOKUP(B21,'[5]2023'!$A$3:$AK$1248,37,FALSE),"") -> 3.3333333
A22: C | B22: CCE0053 | C22: Cabo Embreagem Moto | D22: POLO | E22: CCE0053 CABO EMBREAGEM HONDA POP 110 16> | F22: 0 | G22: 0 | H22: 0 | I22: =IFERROR(AVERAGE(F22:H22,),"-") -> 0 | J22: =IFERROR(VLOOKUP(B22,'[5]2023'!$A$3:$AK$1248,37,FALSE),"") -> 3
A23: C | B23: CCA0036 | C23: Cabo Acelerador Moto | D23: POLO | E23: CCA0036 CABO ACELERADOR HONDA CG NXR 150 BROS ES KS 09>12 | F23: 0 | G23: 0 | H23: 0 | I23: =IFERROR(AVERAGE(F23:H23,),"-") -> 0 | J23: =IFERROR(VLOOKUP(B23,'[5]2023'!$A$3:$AK$1248,37,FALSE),"") -> 1.6666667
A24: C | B24: CCE0051 | C24: Cabo Embreagem Moto | D24: POLO | E24: CCE0051 CABO EMBREAGEM HONDA BROS 160 16> | F24: 0 | G24: 0 | H24: 0 | I24: =IFERROR(AVERAGE(F24:H24,),"-") -> 0 | J24: =IFERROR(VLOOKUP(B24,'[5]2023'!$A$3:$AK$1248,37,FALSE),"") -> 1.6666667
A25: C | B25: CCE0056 | C25: Cabo Embreagem Moto | D25: POLO | E25: CCE0056 CABO EMBREAGEM HONDA CG 150 TITAN ES/KS 09> | F25: 0 | G25: 0 | H25: 0 | I25: =IFERROR(AVERAGE(F25:H25,),"-") -> 0 | J25: =IFERROR(VLOOKUP(B25,'[5]2023'!$A$3:$AK$1248,37,FALSE),"") -> 1.6666667
A26: C | B26: CCE0047 | C26: Cabo Embreagem Moto | D26: POLO | E26: CCE0047 CABO EMBREAGEM HONDA NXR 150 BROS ESD 08> | F26: 0 | G26: 0 | H26: 0 | I26: =IFERROR(AVERAGE(F26:H26,),"-") -> 0 | J26: =IFERROR(VLOOKUP(B26,'[5]2023'!$A$3:$AK$1248,37,FALSE),"") -> 1
A27: C | B27: FTK-CCA0038 | C27: Cabo Acelerador Moto | D27: POLO | E27: Cabo Acelerador CG 150 FAN ESI 2010 EM DIANTE | F27: 0 | G27: 0 | H27: 0 | I27: =IFERROR(AVERAGE(F27:H27,),"-") -> 0 | J27: =IFERROR(VLOOKUP(B27,'[5]2023'!$A$3:$AK$1248,37,FALSE),"") -> 0
A28: C | B28: FTK-CCA0041 | C28: Cabo Acelerador Moto | D28: POLO | E28: Cabo Acelerador FAN 160 2016 EM DIANTE | F28: 0 | G28: 0 | H28: 0 | I28: =IFERROR(AVERAGE(F28:H28,),"-") -> 0 | J28: =IFERROR(VLOOKUP(B28,'[5]2023'!$A$3:$AK$1248,37,FALSE),"") -> 0
A29: C | B29: CCA0002 | C29: Cabo Acelerador Moto | D29: POLO | E29: CCA0002 CABO ACELERADOR HONDA CG 125 TITAN ES-JOB-KS-EX DE .../ ATE 2008 CG 150 TITAN EX de ... até 2008 | F29: 0 | G29: 0 | H29: 0 | I29: =IFERROR(AVERAGE(F29:H29,),"-") -> 0 | J29: =IFERROR(VLOOKUP(B29,'[5]2023'!$A$3:$AK$1248,37,FALSE),"") -> 0
A30: C | B30: CCA0009 | C30: Cabo Acelerador Moto | D30: POLO | E30: CCA0009 CABO ACELERADOR HONDA CG 150 FAN-TITAN 14/... | F30: 0 | G30: 0 | H30: 0 | I30: =IFERROR(AVERAGE(F30:H30,),"-") -> 0 | J30: =IFERROR(VLOOKUP(B30,'[5]2023'!$A$3:$AK$1248,37,FALSE),"") -> 0
A31: C | B31: CCA0035 | C31: Cabo Acelerador Moto | D31: POLO | E31: CCA0035 CABO ACELERADOR HONDA CG 150 TITAN MIX ESD 2009/... | F31: 0 | G31: 0 | H31: 0 | I31: =IFERROR(AVERAGE(F31:H31,),"-") -> 0 | J31: =IFERROR(VLOOKUP(B31,'[5]2023'!$A$3:$AK$1248,37,FALSE),"") -> 0
A32: C | B32: CCE0015 | C32: Cabo Embreagem moto | D32: POLO | F32: 0 | G32: 0 | H32: 0 | I32: =IFERROR(AVERAGE(F32:H32,),"-") -> 0 | J32: =IFERROR(VLOOKUP(B32,'[5]2023'!$A$3:$AK$1248,37,FALSE),"") -> 0
A33: C | B33: CCE0012 | C33: Cabo Embreagem moto | D33: POLO | F33: 0 | G33: 0 | H33: 0 | I33: =IFERROR(AVERAGE(F33:H33,),"-") -> 0 | J33: =IFERROR(VLOOKUP(B33,'[5]2023'!$A$3:$AK$1248,37,FALSE),"") -> 0
A34: C | B34: CCE0010 | C34: Cabo Embreagem moto | D34: POLO | F34: 0 | G34: 0 | H34: 0 | I34: =IFERROR(AVERAGE(F34:H34,),"-") -> 0 | J34: =IFERROR(VLOOKUP(B34,'[5]2023'!$A$3:$AK$1248,37,FALSE),"") -> 0
A35: C | B35: CCV0027 | C35: Cabo velocímetro Moto | D35: POLO | E35: CCV0027 CABO VELOCIMETRO HONDA CG 150 TITAN KS/ES/JOB 08> | F35: 0 | G35: 0 | H35: 0 | I35: =IFERROR(AVERAGE(F35:H35,),"-") -> 0 | J35: =IFERROR(VLOOKUP(B35,'[5]2023'!$A$3:$AK$1248,37,FALSE),"") -> 0
